{
 "cells": [
  {
   "cell_type": "code",
   "execution_count": 1,
   "id": "56ae3129",
   "metadata": {},
   "outputs": [
    {
     "name": "stderr",
     "output_type": "stream",
     "text": [
      "/Users/gedena/miniconda3/lib/python3.10/site-packages/scipy/__init__.py:146: UserWarning: A NumPy version >=1.16.5 and <1.23.0 is required for this version of SciPy (detected version 1.23.0\n",
      "  warnings.warn(f\"A NumPy version >={np_minversion} and <{np_maxversion}\"\n",
      "2023-04-09 23:32:06.740999: I tensorflow/core/common_runtime/pluggable_device/pluggable_device_factory.cc:305] Could not identify NUMA node of platform GPU ID 0, defaulting to 0. Your kernel may not have been built with NUMA support.\n",
      "2023-04-09 23:32:06.744872: I tensorflow/core/common_runtime/pluggable_device/pluggable_device_factory.cc:271] Created TensorFlow device (/job:localhost/replica:0/task:0/device:GPU:0 with 0 MB memory) -> physical PluggableDevice (device: 0, name: METAL, pci bus id: <undefined>)\n"
     ]
    },
    {
     "name": "stdout",
     "output_type": "stream",
     "text": [
      "Metal device set to: Apple M2\n",
      "Epoch 1/5\n"
     ]
    },
    {
     "name": "stderr",
     "output_type": "stream",
     "text": [
      "2023-04-09 23:32:07.108328: W tensorflow/core/platform/profile_utils/cpu_utils.cc:128] Failed to get CPU frequency: 0 Hz\n"
     ]
    },
    {
     "ename": "ValueError",
     "evalue": "in user code:\n\n    File \"/Users/gedena/miniconda3/lib/python3.10/site-packages/keras/engine/training.py\", line 1051, in train_function  *\n        return step_function(self, iterator)\n    File \"/Users/gedena/miniconda3/lib/python3.10/site-packages/keras/engine/training.py\", line 1040, in step_function  **\n        outputs = model.distribute_strategy.run(run_step, args=(data,))\n    File \"/Users/gedena/miniconda3/lib/python3.10/site-packages/keras/engine/training.py\", line 1030, in run_step  **\n        outputs = model.train_step(data)\n    File \"/Users/gedena/miniconda3/lib/python3.10/site-packages/keras/engine/training.py\", line 889, in train_step\n        y_pred = self(x, training=True)\n    File \"/Users/gedena/miniconda3/lib/python3.10/site-packages/keras/utils/traceback_utils.py\", line 67, in error_handler\n        raise e.with_traceback(filtered_tb) from None\n    File \"/Users/gedena/miniconda3/lib/python3.10/site-packages/keras/engine/input_spec.py\", line 264, in assert_input_compatibility\n        raise ValueError(f'Input {input_index} of layer \"{layer_name}\" is '\n\n    ValueError: Input 0 of layer \"sequential\" is incompatible with the layer: expected shape=(None, 28, 28), found shape=(32, 784)\n",
     "output_type": "error",
     "traceback": [
      "\u001b[0;31m---------------------------------------------------------------------------\u001b[0m",
      "\u001b[0;31mValueError\u001b[0m                                Traceback (most recent call last)",
      "Cell \u001b[0;32mIn[1], line 25\u001b[0m\n\u001b[1;32m     23\u001b[0m \u001b[38;5;66;03m# Train the model\u001b[39;00m\n\u001b[1;32m     24\u001b[0m start_time \u001b[38;5;241m=\u001b[39m time\u001b[38;5;241m.\u001b[39mtime()\n\u001b[0;32m---> 25\u001b[0m history \u001b[38;5;241m=\u001b[39m \u001b[43mmodel\u001b[49m\u001b[38;5;241;43m.\u001b[39;49m\u001b[43mfit\u001b[49m\u001b[43m(\u001b[49m\u001b[43mtrain_images\u001b[49m\u001b[43m,\u001b[49m\u001b[43m \u001b[49m\u001b[43mtrain_labels\u001b[49m\u001b[43m,\u001b[49m\u001b[43m \u001b[49m\u001b[43mepochs\u001b[49m\u001b[38;5;241;43m=\u001b[39;49m\u001b[38;5;241;43m5\u001b[39;49m\u001b[43m,\u001b[49m\u001b[43m \u001b[49m\u001b[43mvalidation_data\u001b[49m\u001b[38;5;241;43m=\u001b[39;49m\u001b[43m(\u001b[49m\u001b[43mtest_images\u001b[49m\u001b[43m,\u001b[49m\u001b[43m \u001b[49m\u001b[43mtest_labels\u001b[49m\u001b[43m)\u001b[49m\u001b[43m)\u001b[49m\n\u001b[1;32m     26\u001b[0m end_time \u001b[38;5;241m=\u001b[39m time\u001b[38;5;241m.\u001b[39mtime()\n\u001b[1;32m     27\u001b[0m \u001b[38;5;66;03m# Evaluate the model\u001b[39;00m\n",
      "File \u001b[0;32m~/miniconda3/lib/python3.10/site-packages/keras/utils/traceback_utils.py:67\u001b[0m, in \u001b[0;36mfilter_traceback.<locals>.error_handler\u001b[0;34m(*args, **kwargs)\u001b[0m\n\u001b[1;32m     65\u001b[0m \u001b[38;5;28;01mexcept\u001b[39;00m \u001b[38;5;167;01mException\u001b[39;00m \u001b[38;5;28;01mas\u001b[39;00m e:  \u001b[38;5;66;03m# pylint: disable=broad-except\u001b[39;00m\n\u001b[1;32m     66\u001b[0m   filtered_tb \u001b[38;5;241m=\u001b[39m _process_traceback_frames(e\u001b[38;5;241m.\u001b[39m__traceback__)\n\u001b[0;32m---> 67\u001b[0m   \u001b[38;5;28;01mraise\u001b[39;00m e\u001b[38;5;241m.\u001b[39mwith_traceback(filtered_tb) \u001b[38;5;28;01mfrom\u001b[39;00m \u001b[38;5;28mNone\u001b[39m\n\u001b[1;32m     68\u001b[0m \u001b[38;5;28;01mfinally\u001b[39;00m:\n\u001b[1;32m     69\u001b[0m   \u001b[38;5;28;01mdel\u001b[39;00m filtered_tb\n",
      "File \u001b[0;32m/var/folders/1t/sj3jytd91z53kgnkw3mqp59r0000gn/T/__autograph_generated_filemrhnj4_f.py:15\u001b[0m, in \u001b[0;36mouter_factory.<locals>.inner_factory.<locals>.tf__train_function\u001b[0;34m(iterator)\u001b[0m\n\u001b[1;32m     13\u001b[0m \u001b[38;5;28;01mtry\u001b[39;00m:\n\u001b[1;32m     14\u001b[0m     do_return \u001b[38;5;241m=\u001b[39m \u001b[38;5;28;01mTrue\u001b[39;00m\n\u001b[0;32m---> 15\u001b[0m     retval_ \u001b[38;5;241m=\u001b[39m ag__\u001b[38;5;241m.\u001b[39mconverted_call(ag__\u001b[38;5;241m.\u001b[39mld(step_function), (ag__\u001b[38;5;241m.\u001b[39mld(\u001b[38;5;28mself\u001b[39m), ag__\u001b[38;5;241m.\u001b[39mld(iterator)), \u001b[38;5;28;01mNone\u001b[39;00m, fscope)\n\u001b[1;32m     16\u001b[0m \u001b[38;5;28;01mexcept\u001b[39;00m:\n\u001b[1;32m     17\u001b[0m     do_return \u001b[38;5;241m=\u001b[39m \u001b[38;5;28;01mFalse\u001b[39;00m\n",
      "\u001b[0;31mValueError\u001b[0m: in user code:\n\n    File \"/Users/gedena/miniconda3/lib/python3.10/site-packages/keras/engine/training.py\", line 1051, in train_function  *\n        return step_function(self, iterator)\n    File \"/Users/gedena/miniconda3/lib/python3.10/site-packages/keras/engine/training.py\", line 1040, in step_function  **\n        outputs = model.distribute_strategy.run(run_step, args=(data,))\n    File \"/Users/gedena/miniconda3/lib/python3.10/site-packages/keras/engine/training.py\", line 1030, in run_step  **\n        outputs = model.train_step(data)\n    File \"/Users/gedena/miniconda3/lib/python3.10/site-packages/keras/engine/training.py\", line 889, in train_step\n        y_pred = self(x, training=True)\n    File \"/Users/gedena/miniconda3/lib/python3.10/site-packages/keras/utils/traceback_utils.py\", line 67, in error_handler\n        raise e.with_traceback(filtered_tb) from None\n    File \"/Users/gedena/miniconda3/lib/python3.10/site-packages/keras/engine/input_spec.py\", line 264, in assert_input_compatibility\n        raise ValueError(f'Input {input_index} of layer \"{layer_name}\" is '\n\n    ValueError: Input 0 of layer \"sequential\" is incompatible with the layer: expected shape=(None, 28, 28), found shape=(32, 784)\n"
     ]
    }
   ],
   "source": [
    "import tensorflow as tf\n",
    "import numpy as np\n",
    "import time\n",
    "# Load and preprocess the dataset\n",
    "fashion_mnist = tf.keras.datasets.fashion_mnist\n",
    "(train_images, train_labels), (test_images, test_labels) = fashion_mnist.load_data()\n",
    "train_images = train_images.reshape((60000, 28 * 28))\n",
    "train_images = train_images / 255.0\n",
    "test_images = test_images.reshape((10000, 28 * 28))\n",
    "test_images = test_images / 255.0\n",
    "\n",
    "# Define the model architecture\n",
    "model = tf.keras.Sequential([\n",
    "    tf.keras.layers.Flatten(input_shape=(28, 28,)),\n",
    "    tf.keras.layers.Dense(10, activation='softmax')\n",
    "])\n",
    "\n",
    "# Compile the model\n",
    "model.compile(optimizer='adam',\n",
    "              loss='sparse_categorical_crossentropy',\n",
    "              metrics=['accuracy'])\n",
    "\n",
    "# Train the model\n",
    "start_time = time.time()\n",
    "history = model.fit(train_images, train_labels, epochs=5, validation_data=(test_images, test_labels))\n",
    "end_time = time.time()\n",
    "# Evaluate the model\n",
    "test_loss, test_acc = model.evaluate(test_images, test_labels, verbose=2)\n",
    "print('Test accuracy:', test_acc)\n",
    "print('Time elapsed: ', start_time-end_time)\n"
   ]
  },
  {
   "cell_type": "code",
   "execution_count": null,
   "id": "54c1d63e",
   "metadata": {},
   "outputs": [],
   "source": []
  },
  {
   "cell_type": "code",
   "execution_count": null,
   "id": "bfc75fff",
   "metadata": {},
   "outputs": [],
   "source": []
  }
 ],
 "metadata": {
  "kernelspec": {
   "display_name": "Python 3.10 (tensorflow)",
   "language": "python",
   "name": "tensorflow"
  },
  "language_info": {
   "codemirror_mode": {
    "name": "ipython",
    "version": 3
   },
   "file_extension": ".py",
   "mimetype": "text/x-python",
   "name": "python",
   "nbconvert_exporter": "python",
   "pygments_lexer": "ipython3",
   "version": "3.10.9"
  }
 },
 "nbformat": 4,
 "nbformat_minor": 5
}
